<sdf version='1.7'>
  <world name='default'>
    <light name='sun' type='directional'>
      <cast_shadows>1</cast_shadows>
      <pose>0 0 10 0 -0 0</pose>
      <diffuse>0.8 0.8 0.8 1</diffuse>
      <specular>0.2 0.2 0.2 1</specular>
      <attenuation>
        <range>1000</range>
        <constant>0.9</constant>
        <linear>0.01</linear>
        <quadratic>0.001</quadratic>
      </attenuation>
      <direction>-0.5 0.1 -0.9</direction>
      <spot>
        <inner_angle>0</inner_angle>
        <outer_angle>0</outer_angle>
        <falloff>0</falloff>
      </spot>
    </light>
    <model name='ground_plane'>
      <static>1</static>
      <link name='link'>
        <collision name='collision'>
          <geometry>
            <plane>
              <normal>0 0 1</normal>
              <size>100 100</size>
            </plane>
          </geometry>
          <surface>
            <contact>
              <collide_bitmask>65535</collide_bitmask>
              <ode/>
            </contact>
            <friction>
              <ode>
                <mu>100</mu>
                <mu2>50</mu2>
              </ode>
              <torsional>
                <ode/>
              </torsional>
            </friction>
            <bounce/>
          </surface>
          <max_contacts>10</max_contacts>
        </collision>
        <visual name='visual'>
          <cast_shadows>0</cast_shadows>
          <geometry>
            <plane>
              <normal>0 0 1</normal>
              <size>100 100</size>
            </plane>
          </geometry>
          <material>
            <script>
              <uri>file://media/materials/scripts/gazebo.material</uri>
              <name>Gazebo/Grey</name>
            </script>
          </material>
        </visual>
        <self_collide>0</self_collide>
        <enable_wind>0</enable_wind>
        <kinematic>0</kinematic>
      </link>
    </model>
    <gravity>0 0 -9.8</gravity>
    <magnetic_field>6e-06 2.3e-05 -4.2e-05</magnetic_field>
    <atmosphere type='adiabatic'/>
    <physics type='ode'>
      <max_step_size>0.001</max_step_size>
      <real_time_factor>1</real_time_factor>
      <real_time_update_rate>1000</real_time_update_rate>
    </physics>
    <scene>
      <ambient>0.4 0.4 0.4 1</ambient>
      <background>0.7 0.7 0.7 1</background>
      <shadows>1</shadows>
    </scene>
    <wind/>
    <spherical_coordinates>
      <surface_model>EARTH_WGS84</surface_model>
      <latitude_deg>0</latitude_deg>
      <longitude_deg>0</longitude_deg>
      <elevation>0</elevation>
      <heading_deg>0</heading_deg>
    </spherical_coordinates>
    <model name='simulated—walking'>
      <pose>-0.318122 0.391765 0 0 -0 0</pose>
      <link name='Wall_1'>
        <collision name='Wall_1_Collision'>
          <geometry>
            <box>
              <size>4.75 0.15 2.5</size>
            </box>
          </geometry>
          <pose>0 0 1.25 0 -0 0</pose>
          <max_contacts>10</max_contacts>
          <surface>
            <contact>
              <ode/>
            </contact>
            <bounce/>
            <friction>
              <torsional>
                <ode/>
              </torsional>
              <ode/>
            </friction>
          </surface>
        </collision>
        <visual name='Wall_1_Visual'>
          <pose>0 0 1.25 0 -0 0</pose>
          <geometry>
            <box>
              <size>4.75 0.15 2.5</size>
            </box>
          </geometry>
          <material>
            <script>
              <uri>file://media/materials/scripts/gazebo.material</uri>
              <name>Gazebo/Grey</name>
            </script>
            <ambient>0.937255 0.160784 0.160784 1</ambient>
          </material>
          <meta>
            <layer>0</layer>
          </meta>
        </visual>
        <pose>-1.53 1.0725 0 0 -0 0</pose>
        <self_collide>0</self_collide>
        <enable_wind>0</enable_wind>
        <kinematic>0</kinematic>
      </link>
      <link name='Wall_2'>
        <collision name='Wall_2_Collision'>
          <geometry>
            <box>
              <size>2.5 0.15 2.5</size>
            </box>
          </geometry>
          <pose>0 0 1.25 0 -0 0</pose>
          <max_contacts>10</max_contacts>
          <surface>
            <contact>
              <ode/>
            </contact>
            <bounce/>
            <friction>
              <torsional>
                <ode/>
              </torsional>
              <ode/>
            </friction>
          </surface>
        </collision>
        <visual name='Wall_2_Visual'>
          <pose>0 0 1.25 0 -0 0</pose>
          <geometry>
            <box>
              <size>2.5 0.15 2.5</size>
            </box>
          </geometry>
          <material>
            <script>
              <uri>file://media/materials/scripts/gazebo.material</uri>
              <name>Gazebo/Grey</name>
            </script>
            <ambient>0.937255 0.160784 0.160784 1</ambient>
          </material>
          <meta>
            <layer>0</layer>
          </meta>
        </visual>
        <pose>0.77 -0.1025 0 0 -0 -1.5708</pose>
        <self_collide>0</self_collide>
        <enable_wind>0</enable_wind>
        <kinematic>0</kinematic>
      </link>
      <link name='Wall_3'>
        <collision name='Wall_3_Collision'>
          <geometry>
            <box>
              <size>3.25 0.15 2.5</size>
            </box>
          </geometry>
          <pose>0 0 1.25 0 -0 0</pose>
          <max_contacts>10</max_contacts>
          <surface>
            <contact>
              <ode/>
            </contact>
            <bounce/>
            <friction>
              <torsional>
                <ode/>
              </torsional>
              <ode/>
            </friction>
          </surface>
        </collision>
        <visual name='Wall_3_Visual'>
          <pose>0 0 1.25 0 -0 0</pose>
          <geometry>
            <box>
              <size>3.25 0.15 2.5</size>
            </box>
          </geometry>
          <material>
            <script>
              <uri>file://media/materials/scripts/gazebo.material</uri>
              <name>Gazebo/Grey</name>
            </script>
            <ambient>0.937255 0.160784 0.160784 1</ambient>
          </material>
          <meta>
            <layer>0</layer>
          </meta>
        </visual>
        <pose>2.32 -1.2775 0 0 -0 0</pose>
        <self_collide>0</self_collide>
        <enable_wind>0</enable_wind>
        <kinematic>0</kinematic>
      </link>
      <link name='Wall_4'>
        <collision name='Wall_4_Collision'>
          <geometry>
            <box>
              <size>0.15 0.15 2.5</size>
            </box>
          </geometry>
          <pose>0 0 1.25 0 -0 0</pose>
          <max_contacts>10</max_contacts>
          <surface>
            <contact>
              <ode/>
            </contact>
            <bounce/>
            <friction>
              <torsional>
                <ode/>
              </torsional>
              <ode/>
            </friction>
          </surface>
        </collision>
        <visual name='Wall_4_Visual'>
          <pose>0 0 1.25 0 -0 0</pose>
          <geometry>
            <box>
              <size>0.15 0.15 2.5</size>
            </box>
          </geometry>
          <material>
            <script>
              <uri>file://media/materials/scripts/gazebo.material</uri>
              <name>Gazebo/Grey</name>
            </script>
            <ambient>1 1 1 1</ambient>
          </material>
          <meta>
            <layer>0</layer>
          </meta>
        </visual>
        <pose>3.87 -1.2775 0 0 -0 0</pose>
        <self_collide>0</self_collide>
        <enable_wind>0</enable_wind>
        <kinematic>0</kinematic>
      </link>
      <link name='Wall_5'>
        <collision name='Wall_5_Collision'>
          <geometry>
            <box>
              <size>0.15 0.15 2.5</size>
            </box>
          </geometry>
          <pose>0 0 1.25 0 -0 0</pose>
          <max_contacts>10</max_contacts>
          <surface>
            <contact>
              <ode/>
            </contact>
            <bounce/>
            <friction>
              <torsional>
                <ode/>
              </torsional>
              <ode/>
            </friction>
          </surface>
        </collision>
        <visual name='Wall_5_Visual'>
          <pose>0 0 1.25 0 -0 0</pose>
          <geometry>
            <box>
              <size>0.15 0.15 2.5</size>
            </box>
          </geometry>
          <material>
            <script>
              <uri>file://media/materials/scripts/gazebo.material</uri>
              <name>Gazebo/Grey</name>
            </script>
            <ambient>1 1 1 1</ambient>
          </material>
          <meta>
            <layer>0</layer>
          </meta>
        </visual>
        <pose>3.87 -1.2775 0 0 -0 0</pose>
        <self_collide>0</self_collide>
        <enable_wind>0</enable_wind>
        <kinematic>0</kinematic>
      </link>
      <link name='Wall_7'>
        <collision name='Wall_7_Collision'>
          <geometry>
            <box>
              <size>3.5 0.15 2.5</size>
            </box>
          </geometry>
          <pose>0 0 1.25 0 -0 0</pose>
          <max_contacts>10</max_contacts>
          <surface>
            <contact>
              <ode/>
            </contact>
            <bounce/>
            <friction>
              <torsional>
                <ode/>
              </torsional>
              <ode/>
            </friction>
          </surface>
        </collision>
        <visual name='Wall_7_Visual'>
          <pose>0 0 1.25 0 -0 0</pose>
          <geometry>
            <box>
              <size>3.5 0.15 2.5</size>
            </box>
          </geometry>
          <material>
            <script>
              <uri>file://media/materials/scripts/gazebo.material</uri>
              <name>Gazebo/Grey</name>
            </script>
            <ambient>0.937255 0.160784 0.160784 1</ambient>
          </material>
          <meta>
            <layer>0</layer>
          </meta>
        </visual>
        <pose>-2.195 0.3525 0 0 -0 0</pose>
        <self_collide>0</self_collide>
        <enable_wind>0</enable_wind>
        <kinematic>0</kinematic>
      </link>
      <link name='Wall_8'>
        <collision name='Wall_8_Collision'>
          <geometry>
            <box>
              <size>2.5 0.15 2.5</size>
            </box>
          </geometry>
          <pose>0 0 1.25 0 -0 0</pose>
          <max_contacts>10</max_contacts>
          <surface>
            <contact>
              <ode/>
            </contact>
            <bounce/>
            <friction>
              <torsional>
                <ode/>
              </torsional>
              <ode/>
            </friction>
          </surface>
        </collision>
        <visual name='Wall_8_Visual'>
          <pose>0 0 1.25 0 -0 0</pose>
          <geometry>
            <box>
              <size>2.5 0.15 2.5</size>
            </box>
          </geometry>
          <material>
            <script>
              <uri>file://media/materials/scripts/gazebo.material</uri>
              <name>Gazebo/Grey</name>
            </script>
            <ambient>0.937255 0.160784 0.160784 1</ambient>
          </material>
          <meta>
            <layer>0</layer>
          </meta>
        </visual>
        <pose>-0.52 -0.8225 0 0 -0 -1.5708</pose>
        <self_collide>0</self_collide>
        <enable_wind>0</enable_wind>
        <kinematic>0</kinematic>
      </link>
      <link name='Wall_9'>
        <collision name='Wall_9_Collision'>
          <geometry>
            <box>
              <size>4.5 0.15 2.5</size>
            </box>
          </geometry>
          <pose>0 0 1.25 0 -0 0</pose>
          <max_contacts>10</max_contacts>
          <surface>
            <contact>
              <ode/>
            </contact>
            <bounce/>
            <friction>
              <torsional>
                <ode/>
              </torsional>
              <ode/>
            </friction>
          </surface>
        </collision>
        <visual name='Wall_9_Visual'>
          <pose>0 0 1.25 0 -0 0</pose>
          <geometry>
            <box>
              <size>4.5 0.15 2.5</size>
            </box>
          </geometry>
          <material>
            <script>
              <uri>file://media/materials/scripts/gazebo.material</uri>
              <name>Gazebo/Grey</name>
            </script>
            <ambient>0.937255 0.160784 0.160784 1</ambient>
          </material>
          <meta>
            <layer>0</layer>
          </meta>
        </visual>
        <pose>1.655 -1.9975 0 0 -0 0</pose>
        <self_collide>0</self_collide>
        <enable_wind>0</enable_wind>
        <kinematic>0</kinematic>
      </link>
      <static>1</static>
    </model>
    <model name='miro'>
      <frame name='miro_body::__model__' attached_to='miro_body::body'>
        <pose relative_to='__model__'>0 0 0 0 -0 0</pose>
      </frame>
      <link name='miro_body::body'>
        <inertial>
          <pose>-0.06 0 0.05 0 -0 0</pose>
          <mass>1.5708</mass>
          <inertia>
            <ixx>0.00523599</ixx>
            <ixy>0</ixy>
            <ixz>0</ixz>
            <iyy>0.00523599</iyy>
            <iyz>0</iyz>
            <izz>0.00785398</izz>
          </inertia>
        </inertial>
        <visual name='visual_valance'>
          <pose>0 0 0 0 -0 0</pose>
          <geometry>
            <mesh>
              <uri>model://miro_model/meshes/valance.dae</uri>
            </mesh>
          </geometry>
          <material>
            <script>
              <uri>file://media/materials/scripts/gazebo.material</uri>
              <name>Gazebo/Grey</name>
            </script>
          </material>
        </visual>
        <collision name='collision_valance'>
          <pose>0 0 0 0 -0 0</pose>
          <geometry>
            <mesh>
              <uri>model://miro_model/meshes/valance_collision.dae</uri>
            </mesh>
          </geometry>
          <surface>
            <friction>
              <ode>
                <mu>0.1</mu>
                <mu2>0.1</mu2>
              </ode>
              <torsional>
                <ode/>
              </torsional>
            </friction>
            <contact>
              <ode/>
            </contact>
            <bounce/>
          </surface>
          <max_contacts>10</max_contacts>
        </collision>
        <visual name='visual_skirt_lh'>
          <pose>0 0 0 0 -0 0</pose>
          <geometry>
            <mesh>
              <uri>model://miro_model/meshes/skirt_lh.dae</uri>
            </mesh>
          </geometry>
          <material>
            <script>
              <uri>file://media/materials/scripts/gazebo.material</uri>
              <name>Gazebo/Grey</name>
            </script>
          </material>
        </visual>
        <visual name='visual_skirt_rh'>
          <pose>0 0 0 0 -0 0</pose>
          <geometry>
            <mesh>
              <uri>model://miro_model/meshes/skirt_rh.dae</uri>
            </mesh>
          </geometry>
          <material>
            <script>
              <uri>file://media/materials/scripts/gazebo.material</uri>
              <name>Gazebo/Grey</name>
            </script>
          </material>
        </visual>
        <visual name='visual_cliff_sensor_L_asm'>
          <pose>0 0 0 0 -0 0</pose>
          <geometry>
            <mesh>
              <uri>model://miro_model/meshes/cliff_sensor_L_asm.dae</uri>
            </mesh>
          </geometry>
          <material>
            <script>
              <uri>file://media/materials/scripts/gazebo.material</uri>
              <name>Gazebo/DarkGrey</name>
            </script>
          </material>
        </visual>
        <visual name='visual_cliff_sensor_R_asm'>
          <pose>0 0 0 0 -0 0</pose>
          <geometry>
            <mesh>
              <uri>model://miro_model/meshes/cliff_sensor_R_asm.dae</uri>
            </mesh>
          </geometry>
          <material>
            <script>
              <uri>file://media/materials/scripts/gazebo.material</uri>
              <name>Gazebo/DarkGrey</name>
            </script>
          </material>
        </visual>
        <visual name='visual_light_sensor_holder_asm_L'>
          <pose>0 0 0 0 -0 0</pose>
          <geometry>
            <mesh>
              <uri>model://miro_model/meshes/light_sensor_holder_asm_L.dae</uri>
            </mesh>
          </geometry>
          <material>
            <script>
              <uri>file://media/materials/scripts/gazebo.material</uri>
              <name>Gazebo/DarkGrey</name>
            </script>
          </material>
        </visual>
        <visual name='visual_light_sensor_holder_asm_R'>
          <pose>0 0 0 0 -0 0</pose>
          <geometry>
            <mesh>
              <uri>model://miro_model/meshes/light_sensor_holder_asm_R.dae</uri>
            </mesh>
          </geometry>
          <material>
            <script>
              <uri>file://media/materials/scripts/gazebo.material</uri>
              <name>Gazebo/DarkGrey</name>
            </script>
          </material>
        </visual>
        <visual name='visual_body_shell'>
          <pose>0 0 0 0 -0 0</pose>
          <geometry>
            <mesh>
              <uri>model://miro_model/meshes/body_shell.dae</uri>
            </mesh>
          </geometry>
          <material>
            <script>
              <uri>file://media/materials/scripts/gazebo.material</uri>
              <name>Gazebo/White</name>
            </script>
          </material>
        </visual>
        <collision name='collision_body_shell'>
          <pose>0 0 0 0 -0 0</pose>
          <geometry>
            <mesh>
              <uri>model://miro_model/meshes/body_shell_collision.dae</uri>
            </mesh>
          </geometry>
          <surface>
            <friction>
              <ode>
                <mu>0.1</mu>
                <mu2>0.1</mu2>
              </ode>
              <torsional>
                <ode/>
              </torsional>
            </friction>
            <contact>
              <ode/>
            </contact>
            <bounce/>
          </surface>
          <max_contacts>10</max_contacts>
        </collision>
        <visual name='visual_slider'>
          <pose>0 0 0 0 -0 0</pose>
          <geometry>
            <mesh>
              <uri>model://miro_model/meshes/slider.dae</uri>
            </mesh>
          </geometry>
          <material>
            <script>
              <uri>file://media/materials/scripts/gazebo.material</uri>
              <name>Gazebo/DarkGrey</name>
            </script>
          </material>
        </visual>
        <collision name='collision_slider'>
          <pose>-0.1075 0 0.0264 0 -0 0</pose>
          <geometry>
            <sphere>
              <radius>0.015</radius>
            </sphere>
          </geometry>
          <surface>
            <friction>
              <ode>
                <mu>0.01</mu>
                <mu2>0.01</mu2>
              </ode>
              <torsional>
                <ode/>
              </torsional>
            </friction>
            <contact>
              <ode/>
            </contact>
            <bounce/>
          </surface>
          <max_contacts>10</max_contacts>
        </collision>
        <sensor name='acc_body' type='imu'>
          <pose>0 0 0 0 -0 0</pose>
          <always_on>1</always_on>
          <update_rate>50</update_rate>
          <visualize>0</visualize>
          <imu/>
        </sensor>
        <sensor name='cliff_l' type='sonar'>
          <pose>0.062 0.055 0.085 0 -0.52 0</pose>
          <always_on>1</always_on>
          <update_rate>50</update_rate>
          <visualize>0</visualize>
          <sonar>
            <min>0</min>
            <max>0.5</max>
            <radius>0.025</radius>
          </sonar>
        </sensor>
        <sensor name='cliff_r' type='sonar'>
          <pose>0.062 -0.055 0.085 0 -0.52 0</pose>
          <always_on>1</always_on>
          <update_rate>50</update_rate>
          <visualize>0</visualize>
          <sonar>
            <min>0</min>
            <max>0.5</max>
            <radius>0.025</radius>
          </sonar>
        </sensor>
        <sensor name='lightfl' type='camera'>
          <pose>0.055 0.065 0.08 -0 -0.06 0.52</pose>
          <camera>
            <horizontal_fov>1.57</horizontal_fov>
            <image>
              <width>16</width>
              <height>12</height>
            </image>
            <clip>
              <near>0.01</near>
              <far>10</far>
            </clip>
          </camera>
          <always_on>1</always_on>
          <update_rate>5</update_rate>
          <visualize>0</visualize>
        </sensor>
        <sensor name='lightfr' type='camera'>
          <pose>0.055 -0.065 0.08 0 -0.06 -0.52</pose>
          <camera>
            <horizontal_fov>1.57</horizontal_fov>
            <image>
              <width>16</width>
              <height>12</height>
            </image>
            <clip>
              <near>0.01</near>
              <far>10</far>
            </clip>
          </camera>
          <always_on>1</always_on>
          <update_rate>5</update_rate>
          <visualize>0</visualize>
        </sensor>
        <sensor name='lightrl' type='camera'>
          <pose>-0.125 0.072 0.06 0 -0.26 2.61</pose>
          <camera>
            <horizontal_fov>1.57</horizontal_fov>
            <image>
              <width>16</width>
              <height>12</height>
            </image>
            <clip>
              <near>0.01</near>
              <far>10</far>
            </clip>
          </camera>
          <always_on>1</always_on>
          <update_rate>5</update_rate>
          <visualize>0</visualize>
        </sensor>
        <sensor name='lightrr' type='camera'>
          <pose>-0.125 -0.072 0.06 0 -0.26 -2.61</pose>
          <camera>
            <horizontal_fov>1.57</horizontal_fov>
            <image>
              <width>16</width>
              <height>12</height>
            </image>
            <clip>
              <near>0.01</near>
              <far>10</far>
            </clip>
          </camera>
          <always_on>1</always_on>
          <update_rate>5</update_rate>
          <visualize>0</visualize>
        </sensor>
        <pose relative_to='miro_body::__model__'>0 0 0 0 -0 0</pose>
        <self_collide>0</self_collide>
        <enable_wind>0</enable_wind>
        <kinematic>0</kinematic>
      </link>
      <link name='miro_body::wheel_lh'>
        <inertial>
          <pose>0.00063 0.07779 0.044838 0 -0 0</pose>
          <mass>0.134041</mass>
          <inertia>
            <ixx>0.00014298</ixx>
            <ixy>0</ixy>
            <ixz>0</ixz>
            <iyy>0.00014298</iyy>
            <iyz>0</iyz>
            <izz>0.00014298</izz>
          </inertia>
        </inertial>
        <visual name='visual_wheel_tyre_lh'>
          <pose>0 0 0 0 -0 0</pose>
          <geometry>
            <mesh>
              <uri>model://miro_model/meshes/wheel_tyre_lh.dae</uri>
            </mesh>
          </geometry>
          <material>
            <script>
              <uri>file://media/materials/scripts/gazebo.material</uri>
              <name>Gazebo/DarkGrey</name>
            </script>
          </material>
        </visual>
        <collision name='collision_wheel_tyre_lh'>
          <pose>0.00063 0.07779 0.044838 -1.5446 0 0</pose>
          <geometry>
            <cylinder>
              <radius>0.045</radius>
              <length>0.002</length>
            </cylinder>
          </geometry>
          <surface>
            <friction>
              <ode>
                <mu>1</mu>
                <mu2>1</mu2>
              </ode>
              <torsional>
                <ode/>
              </torsional>
            </friction>
            <contact>
              <ode/>
            </contact>
            <bounce/>
          </surface>
          <max_contacts>10</max_contacts>
        </collision>
        <visual name='visual_wheel_rim_lh'>
          <pose>0 0 0 0 -0 0</pose>
          <geometry>
            <mesh>
              <uri>model://miro_model/meshes/wheel_rim_lh.dae</uri>
            </mesh>
          </geometry>
          <material>
            <script>
              <uri>file://media/materials/scripts/gazebo.material</uri>
              <name>Gazebo/Grey</name>
            </script>
          </material>
        </visual>
        <pose relative_to='miro_body::__model__'>0 0 0 0 -0 0</pose>
        <self_collide>0</self_collide>
        <enable_wind>0</enable_wind>
        <kinematic>0</kinematic>
      </link>
      <link name='miro_body::wheel_rh'>
        <inertial>
          <pose>0.00063 -0.07779 0.044838 0 -0 0</pose>
          <mass>0.134041</mass>
          <inertia>
            <ixx>0.00014298</ixx>
            <ixy>0</ixy>
            <ixz>0</ixz>
            <iyy>0.00014298</iyy>
            <iyz>0</iyz>
            <izz>0.00014298</izz>
          </inertia>
        </inertial>
        <visual name='visual_wheel_tyre_rh'>
          <pose>0 0 0 0 -0 0</pose>
          <geometry>
            <mesh>
              <uri>model://miro_model/meshes/wheel_tyre_rh.dae</uri>
            </mesh>
          </geometry>
          <material>
            <script>
              <uri>file://media/materials/scripts/gazebo.material</uri>
              <name>Gazebo/DarkGrey</name>
            </script>
          </material>
        </visual>
        <collision name='collision_wheel_tyre_rh'>
          <pose>0.00063 -0.07779 0.044838 1.5446 -0 0</pose>
          <geometry>
            <cylinder>
              <radius>0.045</radius>
              <length>0.002</length>
            </cylinder>
          </geometry>
          <surface>
            <friction>
              <ode>
                <mu>1</mu>
                <mu2>1</mu2>
              </ode>
              <torsional>
                <ode/>
              </torsional>
            </friction>
            <contact>
              <ode/>
            </contact>
            <bounce/>
          </surface>
          <max_contacts>10</max_contacts>
        </collision>
        <visual name='visual_wheel_rim_rh'>
          <pose>0 0 0 0 -0 0</pose>
          <geometry>
            <mesh>
              <uri>model://miro_model/meshes/wheel_rim_rh.dae</uri>
            </mesh>
          </geometry>
          <material>
            <script>
              <uri>file://media/materials/scripts/gazebo.material</uri>
              <name>Gazebo/Grey</name>
            </script>
          </material>
        </visual>
        <pose relative_to='miro_body::__model__'>0 0 0 0 -0 0</pose>
        <self_collide>0</self_collide>
        <enable_wind>0</enable_wind>
        <kinematic>0</kinematic>
      </link>
      <joint name='miro_body::body_wheel_lh' type='revolute'>
        <pose>0.00063 0.07779 0.044838 0 -0 0</pose>
        <parent>miro_body::body</parent>
        <child>miro_body::wheel_lh</child>
        <axis>
          <xyz>0 0.999657 0.026185</xyz>
          <dynamics>
            <friction>0.1</friction>
            <damping>0.1</damping>
            <spring_reference>0</spring_reference>
            <spring_stiffness>0</spring_stiffness>
          </dynamics>
          <limit>
            <lower>-1e+16</lower>
            <upper>1e+16</upper>
          </limit>
        </axis>
      </joint>
      <joint name='miro_body::body_wheel_rh' type='revolute'>
        <pose>0.00063 -0.07779 0.044838 0 -0 0</pose>
        <parent>miro_body::body</parent>
        <child>miro_body::wheel_rh</child>
        <axis>
          <xyz>0 0.999657 -0.026185</xyz>
          <dynamics>
            <friction>0.1</friction>
            <damping>0.1</damping>
            <spring_reference>0</spring_reference>
            <spring_stiffness>0</spring_stiffness>
          </dynamics>
          <limit>
            <lower>-1e+16</lower>
            <upper>1e+16</upper>
          </limit>
        </axis>
      </joint>
      <frame name='miro_tail::__model__' attached_to='miro_tail::tail_gmbl'>
        <pose relative_to='__model__'>0 0 0 0 -0 0</pose>
      </frame>
      <link name='miro_tail::tail_gmbl'>
        <inertial>
          <pose>-0.143 0 0.085 0 -0 0</pose>
          <mass>0.056549</mass>
          <inertia>
            <ixx>3.393e-05</ixx>
            <ixy>0</ixy>
            <ixz>0</ixz>
            <iyy>3.393e-05</iyy>
            <iyz>0</iyz>
            <izz>3.393e-05</izz>
          </inertia>
        </inertial>
        <pose relative_to='miro_tail::__model__'>0 0 0 0 -0 0</pose>
        <self_collide>0</self_collide>
        <enable_wind>0</enable_wind>
        <kinematic>0</kinematic>
      </link>
      <joint name='miro_tail::body_tail_gmbl' type='revolute'>
        <pose>-0.143 0 0.085 0 -0 0</pose>
        <parent>miro_body::body</parent>
        <child>miro_tail::tail_gmbl</child>
        <axis>
          <xyz>0 1 0</xyz>
          <limit>
            <lower>-1.57</lower>
            <upper>1.57</upper>
          </limit>
          <dynamics>
            <friction>0.01</friction>
            <damping>0.02</damping>
            <spring_reference>0</spring_reference>
            <spring_stiffness>0</spring_stiffness>
          </dynamics>
        </axis>
      </joint>
      <link name='miro_tail::tail'>
        <inertial>
          <pose>-0.143 0 0.085 0 -0 0</pose>
          <mass>0.056549</mass>
          <inertia>
            <ixx>3.393e-05</ixx>
            <ixy>0</ixy>
            <ixz>0</ixz>
            <iyy>3.393e-05</iyy>
            <iyz>0</iyz>
            <izz>3.393e-05</izz>
          </inertia>
        </inertial>
        <visual name='visual_tail'>
          <pose>0 0 0 0 -0 0</pose>
          <geometry>
            <mesh>
              <uri>model://miro_model/meshes/tail.dae</uri>
            </mesh>
          </geometry>
          <material>
            <script>
              <uri>file://media/materials/scripts/gazebo.material</uri>
              <name>Gazebo/Grey</name>
            </script>
          </material>
        </visual>
        <collision name='collision_tail'>
          <pose>0 0 0 0 -0 0</pose>
          <geometry>
            <mesh>
              <uri>model://miro_model/meshes/tail_collision.dae</uri>
            </mesh>
          </geometry>
          <surface>
            <friction>
              <ode>
                <mu>0.1</mu>
                <mu2>0.1</mu2>
              </ode>
              <torsional>
                <ode/>
              </torsional>
            </friction>
            <contact>
              <ode/>
            </contact>
            <bounce/>
          </surface>
          <max_contacts>10</max_contacts>
        </collision>
        <pose relative_to='miro_tail::__model__'>0 0 0 0 -0 0</pose>
        <self_collide>0</self_collide>
        <enable_wind>0</enable_wind>
        <kinematic>0</kinematic>
      </link>
      <joint name='miro_tail::tail_gmbl_tail' type='revolute'>
        <pose>-0.143 0 0.085 0 -0 0</pose>
        <parent>miro_tail::tail_gmbl</parent>
        <child>miro_tail::tail</child>
        <axis>
          <xyz>0 0 1</xyz>
          <limit>
            <lower>-1.57</lower>
            <upper>1.57</upper>
          </limit>
          <dynamics>
            <friction>0.01</friction>
            <damping>0.02</damping>
            <spring_reference>0</spring_reference>
            <spring_stiffness>0</spring_stiffness>
          </dynamics>
        </axis>
      </joint>
      <joint name='body_neck' type='revolute'>
        <pose>-0.002 0 0.081 0 -0 0</pose>
        <parent>miro_body::body</parent>
        <child>miro_neck::neck</child>
        <axis>
          <xyz>0 1 0</xyz>
          <limit>
            <lower>0</lower>
            <upper>1.57</upper>
          </limit>
          <dynamics>
            <spring_stiffness>0.4</spring_stiffness>
            <spring_reference>0</spring_reference>
            <friction>0.01</friction>
            <damping>0.1</damping>
          </dynamics>
        </axis>
      </joint>
      <frame name='miro_neck::__model__' attached_to='miro_neck::neck'>
        <pose relative_to='__model__'>0 0 0 0 -0 0</pose>
      </frame>
      <link name='miro_neck::neck'>
        <inertial>
          <pose>-0.002 0 0.141 0 -0 0</pose>
          <mass>0.075398</mass>
          <inertia>
            <ixx>9.802e-05</ixx>
            <ixy>0</ixy>
            <ixz>0</ixz>
            <iyy>9.802e-05</iyy>
            <iyz>0</iyz>
            <izz>1.508e-05</izz>
          </inertia>
        </inertial>
        <pose relative_to='miro_neck::__model__'>0 0 0 0 -0 0</pose>
        <self_collide>0</self_collide>
        <enable_wind>0</enable_wind>
        <kinematic>0</kinematic>
      </link>
      <joint name='neck_gmbl' type='revolute'>
        <pose>-0.002 0 0.201 0 -0 0</pose>
        <parent>miro_neck::neck</parent>
        <child>miro_gmbl::gmbl</child>
        <axis>
          <xyz>0 0 1</xyz>
          <limit>
            <lower>-1.57</lower>
            <upper>1.57</upper>
          </limit>
          <dynamics>
            <friction>0.01</friction>
            <damping>0.1</damping>
            <spring_reference>0</spring_reference>
            <spring_stiffness>0</spring_stiffness>
          </dynamics>
        </axis>
      </joint>
      <frame name='miro_gmbl::__model__' attached_to='miro_gmbl::gmbl'>
        <pose relative_to='__model__'>0 0 0 0 -0 0</pose>
      </frame>
      <link name='miro_gmbl::gmbl'>
        <inertial>
          <pose>-0.002 0 0.171 0 -0 0</pose>
          <mass>0.03927</mass>
          <inertia>
            <ixx>2.487e-05</ixx>
            <ixy>0</ixy>
            <ixz>0</ixz>
            <iyy>2.487e-05</iyy>
            <iyz>0</iyz>
            <izz>4.909e-05</izz>
          </inertia>
        </inertial>
        <visual name='visual_collar'>
          <pose>0 0 0 0 -0 0</pose>
          <geometry>
            <mesh>
              <uri>model://miro_model/meshes/collar.dae</uri>
            </mesh>
          </geometry>
          <material>
            <script>
              <uri>file://media/materials/scripts/gazebo.material</uri>
              <name>Gazebo/Red</name>
            </script>
          </material>
        </visual>
        <pose relative_to='miro_gmbl::__model__'>0 0 0 0 -0 0</pose>
        <self_collide>0</self_collide>
        <enable_wind>0</enable_wind>
        <kinematic>0</kinematic>
      </link>
      <joint name='gmbl_head' type='revolute'>
        <pose>-0.002 0 0.201 0 -0 0</pose>
        <parent>miro_gmbl::gmbl</parent>
        <child>miro_head::head</child>
        <axis>
          <xyz>0 1 0</xyz>
          <limit>
            <lower>-1.57</lower>
            <upper>1.57</upper>
          </limit>
          <dynamics>
            <spring_stiffness>0.1</spring_stiffness>
            <spring_reference>-0.5</spring_reference>
            <friction>0.01</friction>
            <damping>0.1</damping>
          </dynamics>
        </axis>
      </joint>
      <frame name='miro_head::__model__' attached_to='miro_head::head'>
        <pose relative_to='__model__'>0 0 0 0 -0 0</pose>
      </frame>
      <link name='miro_head::head'>
        <inertial>
          <pose>-0.002 0 0.221 0 -0 0</pose>
          <mass>0.261799</mass>
          <inertia>
            <ixx>0.00043633</ixx>
            <ixy>0</ixy>
            <ixz>0</ixz>
            <iyy>0.00043633</iyy>
            <iyz>0</iyz>
            <izz>0.00043633</izz>
          </inertia>
        </inertial>
        <visual name='visual_head_lower'>
          <pose>0 0 0 0 -0 0</pose>
          <geometry>
            <mesh>
              <uri>model://miro_model/meshes/head_lower.dae</uri>
            </mesh>
          </geometry>
          <material>
            <script>
              <uri>file://media/materials/scripts/gazebo.material</uri>
              <name>Gazebo/White</name>
            </script>
          </material>
        </visual>
        <collision name='collision_head_lower'>
          <pose>0 0 0 0 -0 0</pose>
          <geometry>
            <mesh>
              <uri>model://miro_model/meshes/head_lower_collision.dae</uri>
            </mesh>
          </geometry>
          <surface>
            <friction>
              <ode>
                <mu>0.1</mu>
                <mu2>0.1</mu2>
              </ode>
              <torsional>
                <ode/>
              </torsional>
            </friction>
            <contact>
              <ode/>
            </contact>
            <bounce/>
          </surface>
          <max_contacts>10</max_contacts>
        </collision>
        <visual name='visual_head_upper'>
          <pose>0 0 0 0 -0 0</pose>
          <geometry>
            <mesh>
              <uri>model://miro_model/meshes/head_upper.dae</uri>
            </mesh>
          </geometry>
          <material>
            <script>
              <uri>file://media/materials/scripts/gazebo.material</uri>
              <name>Gazebo/White</name>
            </script>
          </material>
        </visual>
        <collision name='collision_head_upper'>
          <pose>0 0 0 0 -0 0</pose>
          <geometry>
            <mesh>
              <uri>model://miro_model/meshes/head_upper_collision.dae</uri>
            </mesh>
          </geometry>
          <surface>
            <friction>
              <ode>
                <mu>0.1</mu>
                <mu2>0.1</mu2>
              </ode>
              <torsional>
                <ode/>
              </torsional>
            </friction>
            <contact>
              <ode/>
            </contact>
            <bounce/>
          </surface>
          <max_contacts>10</max_contacts>
        </collision>
        <visual name='visual_eyelid_lower_lh'>
          <pose>0 0 0 0 -0 0</pose>
          <geometry>
            <mesh>
              <uri>model://miro_model/meshes/eyelid_lower_lh.dae</uri>
            </mesh>
          </geometry>
          <material>
            <script>
              <uri>file://media/materials/scripts/gazebo.material</uri>
              <name>Gazebo/White</name>
            </script>
          </material>
        </visual>
        <visual name='visual_eyelid_lower_rh'>
          <pose>0 0 0 0 -0 0</pose>
          <geometry>
            <mesh>
              <uri>model://miro_model/meshes/eyelid_lower_rh.dae</uri>
            </mesh>
          </geometry>
          <material>
            <script>
              <uri>file://media/materials/scripts/gazebo.material</uri>
              <name>Gazebo/White</name>
            </script>
          </material>
        </visual>
        <visual name='visual_nose'>
          <pose>0 0 0 0 -0 0</pose>
          <geometry>
            <mesh>
              <uri>model://miro_model/meshes/nose.dae</uri>
            </mesh>
          </geometry>
          <material>
            <script>
              <uri>file://media/materials/scripts/gazebo.material</uri>
              <name>Gazebo/Grey</name>
            </script>
          </material>
        </visual>
        <collision name='collision_nose'>
          <pose>0 0 0 0 -0 0</pose>
          <geometry>
            <mesh>
              <uri>model://miro_model/meshes/nose_collision.dae</uri>
            </mesh>
          </geometry>
          <surface>
            <friction>
              <ode>
                <mu>0.3</mu>
                <mu2>0.3</mu2>
              </ode>
              <torsional>
                <ode/>
              </torsional>
            </friction>
            <contact>
              <ode/>
            </contact>
            <bounce/>
          </surface>
          <max_contacts>10</max_contacts>
        </collision>
        <visual name='visual_1'>
          <pose>0.029 0.033 0.252 0 -0 0</pose>
          <geometry>
            <sphere>
              <radius>0.018</radius>
            </sphere>
          </geometry>
          <material>
            <script>
              <uri>file://media/materials/scripts/gazebo.material</uri>
              <name>Gazebo/White</name>
            </script>
          </material>
        </visual>
        <visual name='visual_2'>
          <pose>0.0315 0.036 0.254 0 -0 0</pose>
          <geometry>
            <sphere>
              <radius>0.015</radius>
            </sphere>
          </geometry>
          <material>
            <script>
              <uri>file://media/materials/scripts/gazebo.material</uri>
              <name>Gazebo/DarkGrey</name>
            </script>
          </material>
        </visual>
        <visual name='visual_3'>
          <pose>0.029 -0.033 0.252 0 -0 0</pose>
          <geometry>
            <sphere>
              <radius>0.018</radius>
            </sphere>
          </geometry>
          <material>
            <script>
              <uri>file://media/materials/scripts/gazebo.material</uri>
              <name>Gazebo/White</name>
            </script>
          </material>
        </visual>
        <visual name='visual_4'>
          <pose>0.0315 -0.036 0.254 0 -0 0</pose>
          <geometry>
            <sphere>
              <radius>0.015</radius>
            </sphere>
          </geometry>
          <material>
            <script>
              <uri>file://media/materials/scripts/gazebo.material</uri>
              <name>Gazebo/DarkGrey</name>
            </script>
          </material>
        </visual>
        <sensor name='eye_l' type='wideanglecamera'>
          <pose>0.0377 0.0431 0.2595 -0.4262 -0.6816 0.6244</pose>
          <camera>
            <horizontal_fov>2.0944</horizontal_fov>
            <image>
              <width>1280</width>
              <height>720</height>
            </image>
            <clip>
              <near>0.006</near>
              <far>100</far>
            </clip>
            <lens>
              <type>custom</type>
              <scale_to_hfov>1</scale_to_hfov>
              <custom_function>
                <c1>2</c1>
                <c2>1.25</c2>
                <c3>0</c3>
                <f>1</f>
                <fun>sin</fun>
              </custom_function>
            </lens>
          </camera>
          <always_on>1</always_on>
          <update_rate>10</update_rate>
          <visualize>0</visualize>
        </sensor>
        <sensor name='eye_r' type='wideanglecamera'>
          <pose>0.0377 -0.0431 0.2595 0.4261 -0.6816 -0.6244</pose>
          <camera>
            <horizontal_fov>2.0944</horizontal_fov>
            <image>
              <width>1280</width>
              <height>720</height>
            </image>
            <clip>
              <near>0.006</near>
              <far>100</far>
            </clip>
            <lens>
              <type>custom</type>
              <scale_to_hfov>1</scale_to_hfov>
              <custom_function>
                <c1>2</c1>
                <c2>1.25</c2>
                <c3>0</c3>
                <f>1</f>
                <fun>sin</fun>
              </custom_function>
            </lens>
          </camera>
          <always_on>1</always_on>
          <update_rate>10</update_rate>
          <visualize>0</visualize>
        </sensor>
        <sensor name='eye_l_narrow' type='camera'>
          <pose>0.0377 0.0431 0.2595 -0.4262 -0.6816 0.6244</pose>
          <camera>
            <horizontal_fov>2.0944</horizontal_fov>
            <image>
              <width>1280</width>
              <height>720</height>
            </image>
            <clip>
              <near>0.006</near>
              <far>100</far>
            </clip>
          </camera>
          <always_on>1</always_on>
          <update_rate>10</update_rate>
          <visualize>0</visualize>
        </sensor>
        <sensor name='eye_r_narrow' type='camera'>
          <pose>0.0377 -0.0431 0.2595 0.4261 -0.6816 -0.6244</pose>
          <camera>
            <horizontal_fov>2.0944</horizontal_fov>
            <image>
              <width>1280</width>
              <height>720</height>
            </image>
            <clip>
              <near>0.006</near>
              <far>100</far>
            </clip>
          </camera>
          <always_on>1</always_on>
          <update_rate>10</update_rate>
          <visualize>0</visualize>
        </sensor>
        <sensor name='gaze' type='camera'>
          <pose>0.0577 0 0.2795 0 -0.785398 0</pose>
          <camera>
            <horizontal_fov>1</horizontal_fov>
            <image>
              <width>1280</width>
              <height>720</height>
            </image>
            <clip>
              <near>0.001</near>
              <far>100</far>
            </clip>
          </camera>
          <always_on>1</always_on>
          <update_rate>10</update_rate>
          <visualize>0</visualize>
        </sensor>
        <sensor name='overhead' type='camera'>
          <pose>0 0 1 0 1.22 0</pose>
          <camera>
            <horizontal_fov>1.0472</horizontal_fov>
            <image>
              <width>1280</width>
              <height>720</height>
            </image>
            <clip>
              <near>0.01</near>
              <far>2</far>
            </clip>
          </camera>
          <always_on>1</always_on>
          <update_rate>10</update_rate>
          <visualize>0</visualize>
        </sensor>
        <sensor name='acc_head' type='imu'>
          <pose>0 0 0 0 -0 0</pose>
          <always_on>1</always_on>
          <update_rate>50</update_rate>
          <visualize>0</visualize>
          <imu/>
        </sensor>
        <sensor name='sonar' type='sonar'>
          <pose>0.1 0 0.235 3.14159 -1.57079 3.14159</pose>
          <always_on>1</always_on>
          <update_rate>50</update_rate>
          <visualize>0</visualize>
          <sonar>
            <min>0</min>
            <max>1</max>
            <radius>0.309</radius>
          </sonar>
        </sensor>
        <pose relative_to='miro_head::__model__'>0 0 0 0 -0 0</pose>
        <self_collide>0</self_collide>
        <enable_wind>0</enable_wind>
        <kinematic>0</kinematic>
      </link>
      <link name='miro_head::eyelid_lh'>
        <inertial>
          <pose>0.029 0.032 0.252 0 -0 0</pose>
          <mass>0.016755</mass>
          <inertia>
            <ixx>4.47e-06</ixx>
            <ixy>0</ixy>
            <ixz>0</ixz>
            <iyy>4.47e-06</iyy>
            <iyz>0</iyz>
            <izz>4.47e-06</izz>
          </inertia>
        </inertial>
        <visual name='visual_eyelid_lh'>
          <pose>0 0 0 0 -0 0</pose>
          <geometry>
            <mesh>
              <uri>model://miro_model/meshes/eyelid_lh.dae</uri>
            </mesh>
          </geometry>
          <material>
            <script>
              <uri>file://media/materials/scripts/gazebo.material</uri>
              <name>Gazebo/White</name>
            </script>
          </material>
        </visual>
        <pose relative_to='miro_head::__model__'>0 0 0 0 -0 0</pose>
        <self_collide>0</self_collide>
        <enable_wind>0</enable_wind>
        <kinematic>0</kinematic>
      </link>
      <link name='miro_head::eyelid_rh'>
        <inertial>
          <pose>0.029 -0.032 0.252 0 -0 0</pose>
          <mass>0.016755</mass>
          <inertia>
            <ixx>4.47e-06</ixx>
            <ixy>0</ixy>
            <ixz>0</ixz>
            <iyy>4.47e-06</iyy>
            <iyz>0</iyz>
            <izz>4.47e-06</izz>
          </inertia>
        </inertial>
        <visual name='visual_eyelid_rh'>
          <pose>0 0 0 0 -0 0</pose>
          <geometry>
            <mesh>
              <uri>model://miro_model/meshes/eyelid_rh.dae</uri>
            </mesh>
          </geometry>
          <material>
            <script>
              <uri>file://media/materials/scripts/gazebo.material</uri>
              <name>Gazebo/White</name>
            </script>
          </material>
        </visual>
        <pose relative_to='miro_head::__model__'>0 0 0 0 -0 0</pose>
        <self_collide>0</self_collide>
        <enable_wind>0</enable_wind>
        <kinematic>0</kinematic>
      </link>
      <joint name='miro_head::head_eyelid_lh' type='revolute'>
        <pose>0.029 0.032 0.252 0 -0 0</pose>
        <parent>miro_head::head</parent>
        <child>miro_head::eyelid_lh</child>
        <axis>
          <xyz>-0.675 0.675 -0.2978</xyz>
          <limit>
            <lower>-1.57</lower>
            <upper>1.57</upper>
          </limit>
          <dynamics>
            <friction>0.1</friction>
            <damping>0.1</damping>
            <spring_reference>-0.5</spring_reference>
            <spring_stiffness>0.02</spring_stiffness>
          </dynamics>
        </axis>
        <physics>
          <ode>
            <cfm_damping>1</cfm_damping>
            <implicit_spring_damper>1</implicit_spring_damper>
            <limit>
              <cfm>0</cfm>
              <erp>0.2</erp>
            </limit>
          </ode>
        </physics>
      </joint>
      <joint name='miro_head::head_eyelid_rh' type='revolute'>
        <pose>0.029 -0.032 0.252 0 -0 0</pose>
        <parent>miro_head::head</parent>
        <child>miro_head::eyelid_rh</child>
        <axis>
          <xyz>0.675 0.675 0.2978</xyz>
          <limit>
            <lower>-1.57</lower>
            <upper>1.57</upper>
          </limit>
          <dynamics>
            <friction>0.1</friction>
            <damping>0.1</damping>
            <spring_reference>-0.5</spring_reference>
            <spring_stiffness>0.02</spring_stiffness>
          </dynamics>
        </axis>
        <physics>
          <ode>
            <cfm_damping>1</cfm_damping>
            <implicit_spring_damper>1</implicit_spring_damper>
            <limit>
              <cfm>0</cfm>
              <erp>0.2</erp>
            </limit>
          </ode>
        </physics>
      </joint>
      <link name='miro_head::ear_lh'>
        <inertial>
          <pose>-0.0437 0.0474 0.2773 0 -0 0</pose>
          <mass>0.056549</mass>
          <inertia>
            <ixx>3.393e-05</ixx>
            <ixy>0</ixy>
            <ixz>0</ixz>
            <iyy>3.393e-05</iyy>
            <iyz>0</iyz>
            <izz>3.393e-05</izz>
          </inertia>
        </inertial>
        <visual name='visual_ear_lh'>
          <pose>0 0 0 0 -0 0</pose>
          <geometry>
            <mesh>
              <uri>model://miro_model/meshes/ear_lh.dae</uri>
            </mesh>
          </geometry>
          <material>
            <script>
              <uri>file://media/materials/scripts/gazebo.material</uri>
              <name>Gazebo/Grey</name>
            </script>
          </material>
        </visual>
        <collision name='collision_ear_lh'>
          <pose>0 0 0 0 -0 0</pose>
          <geometry>
            <mesh>
              <uri>model://miro_model/meshes/ear_lh_collision.dae</uri>
            </mesh>
          </geometry>
          <surface>
            <friction>
              <ode>
                <mu>0.3</mu>
                <mu2>0.3</mu2>
              </ode>
              <torsional>
                <ode/>
              </torsional>
            </friction>
            <contact>
              <ode/>
            </contact>
            <bounce/>
          </surface>
          <max_contacts>10</max_contacts>
        </collision>
        <pose relative_to='miro_head::__model__'>0 0 0 0 -0 0</pose>
        <self_collide>0</self_collide>
        <enable_wind>0</enable_wind>
        <kinematic>0</kinematic>
      </link>
      <link name='miro_head::ear_rh'>
        <inertial>
          <pose>-0.0437 -0.0474 0.2773 0 -0 0</pose>
          <mass>0.056549</mass>
          <inertia>
            <ixx>3.393e-05</ixx>
            <ixy>0</ixy>
            <ixz>0</ixz>
            <iyy>3.393e-05</iyy>
            <iyz>0</iyz>
            <izz>3.393e-05</izz>
          </inertia>
        </inertial>
        <visual name='visual_ear_rh'>
          <pose>0 0 0 0 -0 0</pose>
          <geometry>
            <mesh>
              <uri>model://miro_model/meshes/ear_rh.dae</uri>
            </mesh>
          </geometry>
          <material>
            <script>
              <uri>file://media/materials/scripts/gazebo.material</uri>
              <name>Gazebo/Grey</name>
            </script>
          </material>
        </visual>
        <collision name='collision_ear_rh'>
          <pose>0 0 0 0 -0 0</pose>
          <geometry>
            <mesh>
              <uri>model://miro_model/meshes/ear_rh_collision.dae</uri>
            </mesh>
          </geometry>
          <surface>
            <friction>
              <ode>
                <mu>0.3</mu>
                <mu2>0.3</mu2>
              </ode>
              <torsional>
                <ode/>
              </torsional>
            </friction>
            <contact>
              <ode/>
            </contact>
            <bounce/>
          </surface>
          <max_contacts>10</max_contacts>
        </collision>
        <pose relative_to='miro_head::__model__'>0 0 0 0 -0 0</pose>
        <self_collide>0</self_collide>
        <enable_wind>0</enable_wind>
        <kinematic>0</kinematic>
      </link>
      <joint name='miro_head::head_ear_lh' type='revolute'>
        <pose>-0.0437 0.0474 0.2773 0 -0 0</pose>
        <parent>miro_head::head</parent>
        <child>miro_head::ear_lh</child>
        <axis>
          <xyz>-0.573 0.4344 0.6949</xyz>
          <limit>
            <lower>-1.57</lower>
            <upper>1.57</upper>
          </limit>
          <dynamics>
            <friction>0.01</friction>
            <damping>0.001</damping>
            <spring_reference>0</spring_reference>
            <spring_stiffness>0</spring_stiffness>
          </dynamics>
        </axis>
      </joint>
      <joint name='miro_head::head_ear_rh' type='revolute'>
        <pose>-0.0437 -0.0474 0.2773 0 -0 0</pose>
        <parent>miro_head::head</parent>
        <child>miro_head::ear_rh</child>
        <axis>
          <xyz>-0.573 -0.4344 0.6949</xyz>
          <limit>
            <lower>-1.57</lower>
            <upper>1.57</upper>
          </limit>
          <dynamics>
            <friction>0.01</friction>
            <damping>0.001</damping>
            <spring_reference>0</spring_reference>
            <spring_stiffness>0</spring_stiffness>
          </dynamics>
        </axis>
      </joint>
      <plugin name='miro_model' filename='libmiro_gazebo.so'/>
      <pose>-3.84395 1.13889 0 0 -0 0</pose>
    </model>
    <state world_name='default'>
      <sim_time>135 452000000</sim_time>
      <real_time>137 798932243</real_time>
      <wall_time>1724258565 123528510</wall_time>
      <iterations>135452</iterations>
      <model name='ground_plane'>
        <pose>0 0 0 0 -0 0</pose>
        <scale>1 1 1</scale>
        <link name='link'>
          <pose>0 0 0 0 -0 0</pose>
          <velocity>0 0 0 0 -0 0</velocity>
          <acceleration>0 0 0 0 -0 0</acceleration>
          <wrench>0 0 0 0 -0 0</wrench>
        </link>
      </model>
      <model name='miro'>
        <pose>-3.84361 1.13958 0.000364 2.9e-05 -0.108205 0.052818</pose>
        <scale>1 1 1</scale>
        <link name='miro_body::body'>
          <pose>-3.84361 1.13958 0.000364 2.9e-05 -0.108205 0.052818</pose>
          <velocity>2.2e-05 0.002279 0.000142 0.060603 0.001966 -0.003694</velocity>
          <acceleration>-0.047431 -0.638354 0.009777 -1.59646 0.230178 2.71067</acceleration>
          <wrench>-0.074504 -1.00273 0.015358 0 -0 0</wrench>
        </link>
        <link name='miro_body::wheel_lh'>
          <pose>-3.84519 1.13948 0.000259 -0.000219 -0.071132 0.053803</pose>
          <velocity>-0.000276 2.7e-05 0.002888 0.027412 0.006767 -0.003622</velocity>
          <acceleration>-0.006649 -2.44899 10.11 -0.183831 -0.145132 1.43082</acceleration>
          <wrench>-0.000891 -0.328265 1.35516 0 -0 0</wrench>
        </link>
        <link name='miro_body::wheel_rh'>
          <pose>-3.845 1.13952 0.000267 0.000236 -0.0757 0.051957</pose>
          <velocity>0.000197 0.0001 -0.002617 0.02784 0.00084 -0.003522</velocity>
          <acceleration>0.028473 -2.42162 -10.1475 -2.26639 0.687225 1.87355</acceleration>
          <wrench>0.003817 -0.324596 -1.36018 0 -0 0</wrench>
        </link>
        <link name='miro_gmbl::gmbl'>
          <pose>-3.88967 1.13714 0.007786 7e-06 0.476683 0.052816</pose>
          <velocity>0.000232 -0.000689 8e-05 0.020615 0.000684 -0.008592</velocity>
          <acceleration>0.485096 -9.13319 0.087221 -2.55953 0.760654 -1.9084</acceleration>
          <wrench>0.01905 -0.35866 0.003425 0 -0 0</wrench>
        </link>
        <link name='miro_head::ear_lh'>
          <pose>-3.87487 1.15985 -2.4e-05 0.043829 0.397928 -0.085564</pose>
          <velocity>0.00055 -0.013016 -0.000856 -0.040491 -0.003129 0.025847</velocity>
          <acceleration>-2.95866 0.642029 -4.12014 -2.52933 1.43327 -0.947226</acceleration>
          <wrench>-0.16731 0.036306 -0.23299 0 -0 0</wrench>
        </link>
        <link name='miro_head::ear_rh'>
          <pose>-3.87333 1.11695 0.000253 -0.041816 0.40099 0.185354</pose>
          <velocity>0.001639 -0.012905 0.000891 -0.040051 -0.002954 0.026009</velocity>
          <acceleration>2.93953 0.840661 4.42494 1.64872 1.50122 2.32692</acceleration>
          <wrench>0.166228 0.047539 0.250226 0 -0 0</wrench>
        </link>
        <link name='miro_head::eyelid_lh'>
          <pose>-3.83317 1.20683 -0.02138 0.288418 0.199598 0.133005</pose>
          <velocity>-1.4e-05 -0.012075 -0.002746 -0.037492 -0.005615 0.026147</velocity>
          <acceleration>-1.91575 -0.990608 -2.7223 0.323713 0.471287 2.58332</acceleration>
          <wrench>-0.032098 -0.016598 -0.045612 0 -0 0</wrench>
        </link>
        <link name='miro_head::eyelid_rh'>
          <pose>-3.79602 1.04414 -0.022793 -0.40645 0.072469 -0.036094</pose>
          <velocity>0.002897 -0.011199 0.004033 -0.037651 -6.7e-05 0.026001</velocity>
          <acceleration>2.05779 -0.806039 3.08413 -3.12818 1.09861 -0.884512</acceleration>
          <wrench>0.034478 -0.013505 0.051675 0 -0 0</wrench>
        </link>
        <link name='miro_head::head'>
          <pose>-3.88896 1.13718 0.007428 -2.3e-05 0.472733 0.052818</pose>
          <velocity>0.001084 -0.013022 3.2e-05 -0.039696 -0.002954 0.025962</velocity>
          <acceleration>0.285968 -4.92735 0.172221 -0.503955 1.43985 -1.11179</acceleration>
          <wrench>0.074866 -1.28998 0.045087 0 -0 0</wrench>
        </link>
        <link name='miro_neck::neck'>
          <pose>-3.88967 1.13715 0.007786 1.6e-05 0.476676 0.052814</pose>
          <velocity>0.000143 0.003539 -7e-06 0.029914 -0.00028 -0.03262</velocity>
          <acceleration>0.180231 -4.45874 0.037748 -1.13822 -0.376095 0.562379</acceleration>
          <wrench>0.013589 -0.33618 0.002846 0 -0 0</wrench>
        </link>
        <link name='miro_tail::tail'>
          <pose>-3.84374 1.13958 7.2e-05 2.3e-05 -0.106276 0.052871</pose>
          <velocity>-1.4e-05 0.002346 4e-05 0.06003 0.002584 -0.003246</velocity>
          <acceleration>0.12273 -3.67101 -0.011475 -2.13268 -0.01155 -0.779904</acceleration>
          <wrench>0.00694 -0.207592 -0.000649 0 -0 0</wrench>
        </link>
        <link name='miro_tail::tail_gmbl'>
          <pose>-3.84374 1.13957 7.2e-05 2.9e-05 -0.106276 0.052818</pose>
          <velocity>-1.6e-05 0.002366 3.8e-05 0.060261 0.002602 -0.003256</velocity>
          <acceleration>0.123836 -3.66228 -0.013074 -1.64613 -0.018318 -0.79012</acceleration>
          <wrench>0.007003 -0.207098 -0.000739 0 -0 0</wrench>
        </link>
      </model>
      <model name='simulated—walking'>
        <pose>-0.318122 0.391765 0 0 -0 0</pose>
        <scale>1 1 1</scale>
        <link name='Wall_1'>
          <pose>-1.84812 1.46426 0 0 -0 0</pose>
          <velocity>0 0 0 0 -0 0</velocity>
          <acceleration>0 0 0 0 -0 0</acceleration>
          <wrench>0 0 0 0 -0 0</wrench>
        </link>
        <link name='Wall_2'>
          <pose>0.451878 0.289265 0 0 0 -1.5708</pose>
          <velocity>0 0 0 0 -0 0</velocity>
          <acceleration>0 0 0 0 -0 0</acceleration>
          <wrench>0 0 0 0 -0 0</wrench>
        </link>
        <link name='Wall_3'>
          <pose>2.00188 -0.885735 0 0 -0 0</pose>
          <velocity>0 0 0 0 -0 0</velocity>
          <acceleration>0 0 0 0 -0 0</acceleration>
          <wrench>0 0 0 0 -0 0</wrench>
        </link>
        <link name='Wall_4'>
          <pose>3.55188 -0.885735 0 0 -0 0</pose>
          <velocity>0 0 0 0 -0 0</velocity>
          <acceleration>0 0 0 0 -0 0</acceleration>
          <wrench>0 0 0 0 -0 0</wrench>
        </link>
        <link name='Wall_5'>
          <pose>3.55188 -0.885735 0 0 -0 0</pose>
          <velocity>0 0 0 0 -0 0</velocity>
          <acceleration>0 0 0 0 -0 0</acceleration>
          <wrench>0 0 0 0 -0 0</wrench>
        </link>
        <link name='Wall_7'>
          <pose>-2.51312 0.744265 0 0 -0 0</pose>
          <velocity>0 0 0 0 -0 0</velocity>
          <acceleration>0 0 0 0 -0 0</acceleration>
          <wrench>0 0 0 0 -0 0</wrench>
        </link>
        <link name='Wall_8'>
          <pose>-0.838122 -0.430735 0 0 0 -1.5708</pose>
          <velocity>0 0 0 0 -0 0</velocity>
          <acceleration>0 0 0 0 -0 0</acceleration>
          <wrench>0 0 0 0 -0 0</wrench>
        </link>
        <link name='Wall_9'>
          <pose>1.33688 -1.60573 0 0 -0 0</pose>
          <velocity>0 0 0 0 -0 0</velocity>
          <acceleration>0 0 0 0 -0 0</acceleration>
          <wrench>0 0 0 0 -0 0</wrench>
        </link>
      </model>
      <light name='sun'>
        <pose>0 0 10 0 -0 0</pose>
      </light>
    </state>
    <gui fullscreen='0'>
      <camera name='user_camera'>
        <pose>-9.88039 1.492 2.56927 0 0.327643 -0.42379</pose>
        <view_controller>orbit</view_controller>
        <projection_type>perspective</projection_type>
      </camera>
    </gui>
  </world>
</sdf>
